2024-02-08 01:10:31,607 - root - INFO - ----------------------------- Started new run @ 2024-02-08:0110 ----------------------------
2024-02-08 01:10:31,608 - root - INFO - -----------------------------  GETTING LINKS : data scientist ----------------------------
2024-02-08 01:10:31,608 - root - INFO - Searching for data-scientist
2024-02-08 01:10:44,367 - root - INFO - 	Empty soup, trying again in 5 secs...
2024-02-08 01:10:52,718 - root - INFO - 	Empty soup, trying again in 5 secs...
2024-02-08 01:11:01,234 - root - INFO - 	Empty soup, trying again in 5 secs...
2024-02-08 01:11:09,769 - root - INFO - 	Empty soup, trying again in 5 secs...
2024-02-08 01:11:18,362 - root - INFO - 	Empty soup, trying again in 5 secs...
2024-02-08 01:13:56,777 - root - INFO - Getting page_source
2024-02-08 01:13:57,185 - root - INFO - Unique links: 0
2024-02-08 01:14:07,196 - root - INFO - -----------------------------  GETTING INFO : data scientist ----------------------------
2024-02-08 01:14:07,196 - root - ERROR - "None of ['job_id'] are in the columns"
Traceback (most recent call last):
  File "/home/runner/work/jobs_retriever_automailer/jobs_retriever_automailer/main.py", line 30, in <module>
    df = process_df(main, remove_nulls=True, remove_duplicates=True)
  File "/home/runner/work/jobs_retriever_automailer/jobs_retriever_automailer/modules/utils.py", line 341, in process_df
    df = df.set_index('job_id')
  File "/opt/hostedtoolcache/Python/3.10.13/x64/lib/python3.10/site-packages/pandas/core/frame.py", line 6106, in set_index
    raise KeyError(f"None of {missing} are in the columns")
KeyError: "None of ['job_id'] are in the columns"
