2024-08-13 01:26:38,391 - utils_logger - INFO - ----------------------------- Started new run @ 2024-08-13:0126 ----------------------------
2024-08-13 01:26:38,392 - utils_logger - INFO - -----------------------------  GETTING LINKS : data scientist ----------------------------
2024-08-13 01:26:38,393 - utils_logger - INFO - Searching for data-scientist
2024-08-13 01:26:42,627 - utils_logger - INFO - 	Empty soup, trying again in 5 secs...
2024-08-13 01:26:49,927 - utils_logger - INFO - 	Empty soup, trying again in 5 secs...
2024-08-13 01:26:57,157 - utils_logger - INFO - 	Empty soup, trying again in 5 secs...
2024-08-13 01:27:05,817 - utils_logger - INFO - 	Empty soup, trying again in 5 secs...
2024-08-13 01:27:14,252 - utils_logger - INFO - 	Empty soup, trying again in 5 secs...
2024-08-13 01:29:27,244 - utils_logger - INFO - Getting page_source
2024-08-13 01:29:27,677 - utils_logger - INFO - Unique links: 0
2024-08-13 01:29:37,687 - utils_logger - INFO - -----------------------------  GETTING INFO : data scientist ----------------------------
2024-08-13 01:29:37,687 - utils_logger - ERROR - "None of ['job_id'] are in the columns"
Traceback (most recent call last):
  File "/home/runner/work/jobs_retriever_automailer/jobs_retriever_automailer/main.py", line 30, in <module>
    df = process_df(main, remove_nulls=True, remove_duplicates=True)
  File "/home/runner/work/jobs_retriever_automailer/jobs_retriever_automailer/modules/utils.py", line 341, in process_df
    df = df.set_index('job_id')
  File "/opt/hostedtoolcache/Python/3.10.14/x64/lib/python3.10/site-packages/pandas/core/frame.py", line 6122, in set_index
    raise KeyError(f"None of {missing} are in the columns")
KeyError: "None of ['job_id'] are in the columns"
