2024-01-18 14:32:41,818 - root - INFO - ----------------------------- Started new run @ 2024-01-18:1432 ----------------------------
2024-01-18 14:32:41,819 - root - INFO - -----------------------------  GETTING LINKS : data analyst ----------------------------
2024-01-18 14:32:41,819 - root - INFO - Searching for data-analyst
2024-01-18 14:32:51,081 - root - INFO - 	Empty soup, trying again in 5 secs...
2024-01-18 14:32:58,904 - root - INFO - 	Empty soup, trying again in 5 secs...
2024-01-18 14:33:07,914 - root - INFO - 	Empty soup, trying again in 5 secs...
2024-01-18 14:33:16,834 - root - INFO - 	Empty soup, trying again in 5 secs...
2024-01-18 14:33:25,793 - root - INFO - 	Empty soup, trying again in 5 secs...
2024-01-18 14:37:45,604 - root - INFO - Getting page_source
2024-01-18 14:37:45,787 - root - INFO - Unique links: 0
2024-01-18 14:37:55,797 - root - INFO - -----------------------------  GETTING INFO : data analyst ----------------------------
2024-01-18 14:37:55,798 - root - ERROR - "None of ['job_id'] are in the columns"
Traceback (most recent call last):
  File "/home/runner/work/jobs_retriever_automailer/jobs_retriever_automailer/main.py", line 30, in <module>
    df = process_df(main, remove_nulls=True, remove_duplicates=True)
  File "/home/runner/work/jobs_retriever_automailer/jobs_retriever_automailer/modules/utils.py", line 341, in process_df
    df = df.set_index('job_id')
  File "/opt/hostedtoolcache/Python/3.10.13/x64/lib/python3.10/site-packages/pandas/core/frame.py", line 5870, in set_index
    raise KeyError(f"None of {missing} are in the columns")
KeyError: "None of ['job_id'] are in the columns"
